<?xml version="1.0" ?>
<!-- =================================================================================== -->
<!-- |    This document was autogenerated by xacro from Assembly.xacro                 | -->
<!-- |    EDITING THIS FILE BY HAND IS NOT RECOMMENDED                                 | -->
<!-- =================================================================================== -->
<robot name="Assembly">
  <material name="silver">
    <color rgba="0.700 0.700 0.700 1.000"/>
  </material>
  <transmission name="Obrot 1_tran">
    <type>transmission_interface/SimpleTransmission</type>
    <joint name="Obrot 1">
      <hardwareInterface>hardware_interface/EffortJointInterface</hardwareInterface>
    </joint>
    <actuator name="Obrot 1_actr">
      <hardwareInterface>hardware_interface/EffortJointInterface</hardwareInterface>
      <mechanicalReduction>1</mechanicalReduction>
    </actuator>
  </transmission>
  <transmission name="Obrot 2_tran">
    <type>transmission_interface/SimpleTransmission</type>
    <joint name="Obrot 2">
      <hardwareInterface>hardware_interface/EffortJointInterface</hardwareInterface>
    </joint>
    <actuator name="Obrot 2_actr">
      <hardwareInterface>hardware_interface/EffortJointInterface</hardwareInterface>
      <mechanicalReduction>1</mechanicalReduction>
    </actuator>
  </transmission>
  <transmission name="Obrot 3_tran">
    <type>transmission_interface/SimpleTransmission</type>
    <joint name="Obrot 3">
      <hardwareInterface>hardware_interface/EffortJointInterface</hardwareInterface>
    </joint>
    <actuator name="Obrot 3_actr">
      <hardwareInterface>hardware_interface/EffortJointInterface</hardwareInterface>
      <mechanicalReduction>1</mechanicalReduction>
    </actuator>
  </transmission>
  <transmission name="Obrot 4_tran">
    <type>transmission_interface/SimpleTransmission</type>
    <joint name="Obrot 4">
      <hardwareInterface>hardware_interface/EffortJointInterface</hardwareInterface>
    </joint>
    <actuator name="Obrot 4_actr">
      <hardwareInterface>hardware_interface/EffortJointInterface</hardwareInterface>
      <mechanicalReduction>1</mechanicalReduction>
    </actuator>
  </transmission>
  <gazebo>
    <plugin filename="libgazebo_ros_control.so" name="control"/>
  </gazebo>
  <gazebo reference="base_link">
    <material>Gazebo/Silver</material>
    <mu1>0.2</mu1>
    <mu2>0.2</mu2>
    <selfCollide>true</selfCollide>
    <gravity>true</gravity>
  </gazebo>
  <gazebo reference="Komponent390_1">
    <material>Gazebo/Silver</material>
    <mu1>0.2</mu1>
    <mu2>0.2</mu2>
    <selfCollide>true</selfCollide>
  </gazebo>
  <gazebo reference="Komponent387_1">
    <material>Gazebo/Silver</material>
    <mu1>0.2</mu1>
    <mu2>0.2</mu2>
    <selfCollide>true</selfCollide>
  </gazebo>
  <gazebo reference="Komponent388_1">
    <material>Gazebo/Silver</material>
    <mu1>0.2</mu1>
    <mu2>0.2</mu2>
    <selfCollide>true</selfCollide>
  </gazebo>
  <gazebo reference="Komponent389_1">
    <material>Gazebo/Silver</material>
    <mu1>0.2</mu1>
    <mu2>0.2</mu2>
    <selfCollide>true</selfCollide>
  </gazebo>
  <link name="base_link">
    <inertial>
      <origin rpy="0 0 0" xyz="0.0013626883253200508 8.361136291997719e-05 0.09570081394757393"/>
      <mass value="10.146617382602876"/>
      <inertia ixx="1.038602" ixy="0.063507" ixz="-0.0094" iyy="1.05519" iyz="-0.001771" izz="1.717662"/>
    </inertial>
    <visual>
      <origin rpy="0 0 0" xyz="0 0 0"/>
      <geometry>
        <mesh filename="../meshes/base_link.stl" scale="0.001 0.001 0.001"/>
      </geometry>
      <material name="silver"/>
    </visual>
    <collision>
      <origin rpy="0 0 0" xyz="0 0 0"/>
      <geometry>
        <mesh filename="../meshes/base_link.stl" scale="0.001 0.001 0.001"/>
      </geometry>
    </collision>
  </link>
  <link name="Komponent390_1">
    <inertial>
      <origin rpy="0 0 0" xyz="1.7396688488102718e-06 0.07158422548093257 -3.680155703067456e-06"/>
      <mass value="3.509196383820251"/>
      <inertia ixx="0.015316" ixy="1e-06" ixz="0.0" iyy="0.020222" iyz="-1e-06" izz="0.015316"/>
    </inertial>
    <visual>
      <origin rpy="0 0 0" xyz="-0.462407 -0.333391 0.181736"/>
      <geometry>
        <mesh filename="../meshes/Komponent390_1.stl" scale="0.001 0.001 0.001"/>
      </geometry>
      <material name="silver"/>
    </visual>
    <collision>
      <origin rpy="0 0 0" xyz="-0.462407 -0.333391 0.181736"/>
      <geometry>
        <mesh filename="../meshes/Komponent390_1.stl" scale="0.001 0.001 0.001"/>
      </geometry>
    </collision>
  </link>
  <link name="Komponent387_1">
    <inertial>
      <origin rpy="0 0 0" xyz="-2.5653229020483614e-06 -0.07158405235834175 -3.5042770395177225e-06"/>
      <mass value="3.50919641521173"/>
      <inertia ixx="0.015316" ixy="1e-06" ixz="-0.0" iyy="0.020222" iyz="1e-06" izz="0.015316"/>
    </inertial>
    <visual>
      <origin rpy="0 0 0" xyz="-0.461782 0.330009 0.182625"/>
      <geometry>
        <mesh filename="../meshes/Komponent387_1.stl" scale="0.001 0.001 0.001"/>
      </geometry>
      <material name="silver"/>
    </visual>
    <collision>
      <origin rpy="0 0 0" xyz="-0.461782 0.330009 0.182625"/>
      <geometry>
        <mesh filename="../meshes/Komponent387_1.stl" scale="0.001 0.001 0.001"/>
      </geometry>
    </collision>
  </link>
  <link name="Komponent388_1">
    <inertial>
      <origin rpy="0 0 0" xyz="2.521271106392664e-06 0.07158422285030919 -3.6801312563450317e-06"/>
      <mass value="3.509196938643843"/>
      <inertia ixx="0.015316" ixy="1e-06" ixz="0.0" iyy="0.020223" iyz="-1e-06" izz="0.015316"/>
    </inertial>
    <visual>
      <origin rpy="0 0 0" xyz="0.460769 -0.333391 0.181736"/>
      <geometry>
        <mesh filename="../meshes/Komponent388_1.stl" scale="0.001 0.001 0.001"/>
      </geometry>
      <material name="silver"/>
    </visual>
    <collision>
      <origin rpy="0 0 0" xyz="0.460769 -0.333391 0.181736"/>
      <geometry>
        <mesh filename="../meshes/Komponent388_1.stl" scale="0.001 0.001 0.001"/>
      </geometry>
    </collision>
  </link>
  <link name="Komponent389_1">
    <inertial>
      <origin rpy="0 0 0" xyz="-2.069141749050374e-06 -0.07158405236339799 -3.6457523256427926e-06"/>
      <mass value="3.509196414812441"/>
      <inertia ixx="0.015316" ixy="1e-06" ixz="-0.0" iyy="0.020222" iyz="1e-06" izz="0.015316"/>
    </inertial>
    <visual>
      <origin rpy="0 0 0" xyz="0.461392 0.330009 0.180846"/>
      <geometry>
        <mesh filename="../meshes/Komponent389_1.stl" scale="0.001 0.001 0.001"/>
      </geometry>
      <material name="silver"/>
    </visual>
    <collision>
      <origin rpy="0 0 0" xyz="0.461392 0.330009 0.180846"/>
      <geometry>
        <mesh filename="../meshes/Komponent389_1.stl" scale="0.001 0.001 0.001"/>
      </geometry>
    </collision>
  </link>
  <joint name="Obrot 1" type="continuous">
    <origin rpy="0 0 0" xyz="0.462407 0.333391 -0.181736"/>
    <parent link="base_link"/>
    <child link="Komponent390_1"/>
    <axis xyz="0.0 1.0 0.0"/>
  </joint>
  <joint name="Obrot 2" type="continuous">
    <origin rpy="0 0 0" xyz="0.461782 -0.330009 -0.182625"/>
    <parent link="base_link"/>
    <child link="Komponent387_1"/>
    <axis xyz="-0.0 1.0 -0.0"/>
  </joint>
  <joint name="Obrot 3" type="continuous">
    <origin rpy="0 0 0" xyz="-0.460769 0.333391 -0.181736"/>
    <parent link="base_link"/>
    <child link="Komponent388_1"/>
    <axis xyz="0.0 -1.0 -0.0"/>
  </joint>
  <joint name="Obrot 4" type="continuous">
    <origin rpy="0 0 0" xyz="-0.461392 -0.330009 -0.180846"/>
    <parent link="base_link"/>
    <child link="Komponent389_1"/>
    <axis xyz="-0.0 -1.0 0.0"/>
  </joint>
</robot>
